Workbook
Name Levered_Raw_Beta: #REF!
Name Market_Beta: #REF!
Name Market_Beta_Weight: #REF!
Name Raw_Beta_Weight: #REF!

Sheet DCF
B1: AMU
B6: Weighted Average Cost of Capital
B8: All figures are in INR unless stated otherwise
B10: Peer Comps
G11: Debt/ | H11: Debt/ | I11: Levered | J11: Unlevered
B12: Name of the Comps | C12: Country | D12: Total Debt | E12: Total Equity | F12: Tax Rate 1 | G12: Equity | H12: Capital | I12: Beta 2 | J12: Beta 3
B14: Avenue Super. | C14: India | D14: =IFERROR(CompBeta!E3,0) -> 712.91 | E14: =IFERROR(CompBeta!D3,0) -> 248261.6 | F14: 0.3 | G14: =D14/E14 -> 0.002871608 | H14: =D14/(E14+D14) -> 0.0028633855 | I14: =BetaA!O5 -> 0.2970684 | J14: =I14/(1+(1-F14)*G14) -> 0.29647245
B15: Trent | C15: India | D15: =IFERROR(CompBeta!E4,0) -> 1842.2 | E15: =IFERROR(CompBeta!D4,0) -> 244650.38 | F15: 0.3 | G15: =D15/E15 -> 0.007529929 | H15: =D15/(E15+D15) -> 0.007473653 | I15: =BetaT!P8 -> 1.0840801 | J15: =I15/(1+(1-F15)*G15) -> 1.0783959
B16: Aditya Bir. Fas. | C16: India | D16: =IFERROR(CompBeta!E5,0) -> 9999.18 | E16: =IFERROR(CompBeta!D5,0) -> 33255.53 | F16: 0.3 | G16: =D16/E16 -> 0.30067721 | H16: =D16/(E16+D16) -> 0.23116974 | I16: 1.36 | J16: =I16/(1+(1-F16)*G16) -> 1.1235268
B17: Metro Brand | C17: India | D17: =IFERROR(CompBeta!E6,0) -> 1573.61 | E17: =IFERROR(CompBeta!D6,0) -> 30481.34 | F17: 0.3 | G17: =D17/E17 -> 0.051625355 | H17: =D17/(E17+D17) -> 0.049091014 | I17: 1.09 | J17: =I17/(1+(1-F17)*G17) -> 1.0519837
E19: Average | F19: =AVERAGE(F14:F18) -> 0.3 | G19: =AVERAGE(G14:G17) -> 0.090676026 | H19: =AVERAGE(H14:H17) -> 0.072649448 | I19: =AVERAGE(I14:I17) -> 0.95778713 | J19: =AVERAGE(J14:J17) -> 0.88759471
E20: Median | F20: =MEDIAN(F14:F18) -> 0.3 | G20: =MEDIAN(G14:G17) -> 0.029577642 | H20: =MEDIAN(H14:H17) -> 0.028282333 | I20: =MEDIAN(I14:I17) -> 1.0870401 | J20: =MEDIAN(J14:J17) -> 1.0651898
B23: Cost of Debt | F23: Cost of Equity
F24: Risk Free Rate | J24: 0.065
B25: Pre-Tax Cost of Debt | D25: 0.084 | F25: Equity Risk Premium | J25: =IFERROR(riskpre!C30-DCF!J24,0) -> 0.091091667
B26: Tax Rate | D26: 0.3 | F26: Levered Beta 4 | J26: =J36 -> 1.1236033
B27: Post-Tax Cost of Debt | D27: =D25*(1-D26) -> 0.0588 | F27: Cost of Equity | J27: =J24+J26*(J25) -> 0.1673509
B31: Capital Structure | F31: Leverage Beta
D33: Current | E33: Target | F33: Comps Median Unlevered Beta | J33: =J20 -> 1.0651898
B34: Total Debt | C34: =D14 -> 712.91 | D34: =C34/$C$36 -> 0.0028633855 | E34: =H19 -> 0.072649448 | F34: Target Debt/Equity | J34: =E38 -> 0.078340869
B35: Market Cap | C35: =E14 -> 248261.6 | D35: =C35/$C$36 -> 0.99713661 | E35: =E36-E34 -> 0.92735055 | F35: Tax Rate | J35: =F20 -> 0.3
B36: Total Cap | C36: =SUM(C34:C35) -> 248974.51 | D36: =SUM(D34:D35) -> 1 | E36: 1 | F36: Levered Beta | J36: =J33*(1+(1-J35)*J34) -> 1.1236033
B38: Debt/Equity | D38: =D34/D35 -> 0.002871608 | E38: =E34/E35 -> 0.078340869 | F38: Weighted Average Cost of Capital
F40: Cost of Equity | J40: =J27 -> 0.1673509
F41: Weigth of Equity | J41: =E35 -> 0.92735055
F43: Cost of Debt | J43: =D27 -> 0.0588
F44: Weight of Debt | J44: =E34 -> 0.072649448
F46: WACC | J46: =(J40*J41)+(J43*J44) -> 0.15946474

Sheet DATA

Sheet BetaT
B2: Regression Beta-5 yrs monthly
B4: Nifty 50 | F4: Trent | J4: Beta Drifting
B6: Date | C6: Closing Price | D6: Return | F6: Date | G6: Closing Price | H6: Return | J6: Levered Raw Beta | K6: =P7 -> 1.0840801
B7: 43831 | C7: 11962.1 | F7: 43831 | G7: 590.8 | J7: Raw Beta Weight | K7: 0.75 | O7: Beta 1 | P7: =SLOPE(H8:H66,BetaT!D8:D66) -> 1.0840801
B8: 43862 | C8: 11201.75 | D8: =(C8-C7)/C7 -> -0.063563254 | F8: 43862 | G8: 737.2 | H8: =(G8-G7)/G7 -> 0.24779959 | O8: Beta 2 | P8: =M43 -> 1.0840801
B9: 43891 | C9: 8597.75 | D9: =(C9-C8)/C8 -> -0.23246368 | F9: 43891 | G9: 484.35 | H9: =(G9-G8)/G8 -> -0.34298698 | J9: Market Beta | K9: 1
B10: 43922 | C10: 9859.9 | D10: =(C10-C9)/C9 -> 0.14680003 | F10: 43922 | G10: 505 | H10: =(G10-G9)/G9 -> 0.042634459 | J10: Market Beta Weight | K10: 0.25
B11: 43952 | C11: 9580.3 | D11: =(C11-C10)/C10 -> -0.028357286 | F11: 43952 | G11: 468.85 | H11: =(G11-G10)/G10 -> -0.071584158
B12: 43983 | C12: 10302.1 | D12: =(C12-C11)/C11 -> 0.075342108 | F12: 43983 | G12: 615.3 | H12: =(G12-G11)/G11 -> 0.31236003
B13: 44013 | C13: 11073.45 | D13: =(C13-C12)/C12 -> 0.074873084 | F13: 44013 | G13: 558.1 | H13: =(G13-G12)/G12 -> -0.092962782 | J13: Adjusted Beta | K13: =(K6*K7)+(K9*K10) -> 1.0630601
B14: 44044 | C14: 11387.5 | D14: =(C14-C13)/C13 -> 0.028360628 | F14: 44044 | G14: 639.2 | H14: =(G14-G13)/G13 -> 0.14531446
B15: 44075 | C15: 11247.55 | D15: =(C15-C14)/C14 -> -0.012289791 | F15: 44075 | G15: 671.9 | H15: =(G15-G14)/G14 -> 0.051157697
B16: 44105 | C16: 11642.4 | D16: =(C16-C15)/C15 -> 0.035105423 | F16: 44105 | G16: 659.55 | H16: =(G16-G15)/G15 -> -0.018380711
B17: 44136 | C17: 12968.95 | D17: =(C17-C16)/C16 -> 0.11394128 | F17: 44136 | G17: 720.3 | H17: =(G17-G16)/G16 -> 0.092108256
B18: 44166 | C18: 13981.75 | D18: =(C18-C17)/C17 -> 0.078094217 | F18: 44166 | G18: 687.6 | H18: =(G18-G17)/G17 -> -0.045397751
B19: 44197 | C19: 13634.6 | D19: =(C19-C18)/C18 -> -0.024828795 | F19: 44197 | G19: 621.55 | H19: =(G19-G18)/G18 -> -0.096058755
B20: 44228 | C20: 14529.15 | D20: =(C20-C19)/C19 -> 0.065608819 | F20: 44228 | G20: 808.65 | H20: =(G20-G19)/G19 -> 0.30102164
B21: 44256 | C21: 14690.7 | D21: =(C21-C20)/C20 -> 0.011119026 | F21: 44256 | G21: 751.05 | H21: =(G21-G20)/G20 -> -0.071229827
B22: 44287 | C22: 14631.1 | D22: =(C22-C21)/C21 -> -0.0040569884 | F22: 44287 | G22: 776.7 | H22: =(G22-G21)/G21 -> 0.034152187
B23: 44317 | C23: 15582.8 | D23: =(C23-C22)/C22 -> 0.065046374 | F23: 44317 | G23: 851.65 | H23: =(G23-G22)/G22 -> 0.096498004
B24: 44348 | C24: 15721.5 | D24: =(C24-C23)/C23 -> 0.0089008394 | F24: 44348 | G24: 849.85 | H24: =(G24-G23)/G23 -> -0.0021135443
B25: 44378 | C25: 15763.05 | D25: =(C25-C24)/C24 -> 0.0026428776 | F25: 44378 | G25: 922.9 | H25: =(G25-G24)/G24 -> 0.085956345
B26: 44409 | C26: 17132.2 | D26: =(C26-C25)/C25 -> 0.086858191 | F26: 44409 | G26: 1006.9 | H26: =(G26-G25)/G25 -> 0.091017445 | L26: SUMMARY OUTPUT
B27: 44440 | C27: 17618.15 | D27: =(C27-C26)/C26 -> 0.028364717 | F27: 44440 | G27: 1025.85 | H27: =(G27-G26)/G26 -> 0.018820141
B28: 44470 | C28: 17671.65 | D28: =(C28-C27)/C27 -> 0.0030366412 | F28: 44470 | G28: 1003.15 | H28: =(G28-G27)/G27 -> -0.022127991 | L28: Regression Statistics
B29: 44501 | C29: 16983.2 | D29: =(C29-C28)/C28 -> -0.038957879 | F29: 44501 | G29: 1014.4 | H29: =(G29-G28)/G28 -> 0.011214674 | L29: Multiple R | M29: 0.50565703
B30: 44531 | C30: 17354.05 | D30: =(C30-C29)/C29 -> 0.021836285 | F30: 44531 | G30: 1065 | H30: =(G30-G29)/G29 -> 0.049881703 | L30: R Square | M30: 0.25568904
B31: 44562 | C31: 17339.85 | D31: =(C31-C30)/C30 -> -0.0008182528 | F31: 44562 | G31: 1031.55 | H31: =(G31-G30)/G30 -> -0.031408451 | L31: Adjusted R Square | M31: 0.24263095
B32: 44593 | C32: 16793.9 | D32: =(C32-C31)/C31 -> -0.031485278 | F32: 44593 | G32: 1108.1 | H32: =(G32-G31)/G31 -> 0.074208715 | L32: Standard Error | M32: 0.10154058
B33: 44621 | C33: 17464.75 | D33: =(C33-C32)/C32 -> 0.039946052 | F33: 44621 | G33: 1275.5 | H33: =(G33-G32)/G32 -> 0.1510694 | L33: Observations | M33: 59
B34: 44652 | C34: 17102.55 | D34: =(C34-C33)/C33 -> -0.020738917 | F34: 44652 | G34: 1228.4 | H34: =(G34-G33)/G33 -> -0.036926695
B35: 44682 | C35: 16584.55 | D35: =(C35-C34)/C34 -> -0.030287881 | F35: 44682 | G35: 1124.05 | H35: =(G35-G34)/G34 -> -0.0849479 | L35: ANOVA
B36: 44713 | C36: 15780.25 | D36: =(C36-C35)/C35 -> -0.048496944 | F36: 44713 | G36: 1074.15 | H36: =(G36-G35)/G35 -> -0.044393043 | M36: df | N36: SS | O36: MS | P36: F | Q36: Significance F
B37: 44743 | C37: 17158.25 | D37: =(C37-C36)/C36 -> 0.087324345 | F37: 44743 | G37: 1268.6 | H37: =(G37-G36)/G36 -> 0.18102686 | L37: Regression | M37: 1 | N37: 0.20188862 | O37: 0.20188862 | P37: 19.580895 | Q37: 4.4046571e-05
B38: 44774 | C38: 17759.3 | D38: =(C38-C37)/C37 -> 0.035029796 | F38: 44774 | G38: 1407.25 | H38: =(G38-G37)/G37 -> 0.10929371 | L38: Residual | M38: 57 | N38: 0.58769792 | O38: 0.01031049
B39: 44805 | C39: 17094.35 | D39: =(C39-C38)/C38 -> -0.037442354 | F39: 44805 | G39: 1420 | H39: =(G39-G38)/G38 -> 0.0090602238 | L39: Total | M39: 58 | N39: 0.78958654
B40: 44835 | C40: 18012.2 | D40: =(C40-C39)/C39 -> 0.053693179 | F40: 44835 | G40: 1527.9 | H40: =(G40-G39)/G39 -> 0.075985915
B41: 44866 | C41: 18758.35 | D41: =(C41-C40)/C40 -> 0.041424701 | F41: 44866 | G41: 1471.65 | H41: =(G41-G40)/G40 -> -0.036815237 | M41: Coefficients | N41: Standard Error | O41: t Stat | P41: P-value | Q41: Lower 95% | R41: Upper 95% | S41: Lower 95.0% | T41: Upper 95.0%
B42: 44896 | C42: 18105.3 | D42: =(C42-C41)/C41 -> -0.03481383 | F42: 44896 | G42: 1351.35 | H42: =(G42-G41)/G41 -> -0.08174498 | L42: Intercept | M42: 0.034056893 | N42: 0.013646623 | O42: 2.4956278 | P42: 0.015491951 | Q42: 0.0067300015 | R42: 0.061383784 | S42: 0.0067300015 | T42: 0.061383784
B43: 44927 | C43: 17662.15 | D43: =(C43-C42)/C42 -> -0.024476258 | F43: 44927 | G43: 1196.6 | H43: =(G43-G42)/G42 -> -0.11451511 | L43: X Variable 1 | M43: 1.0840801 | N43: 0.24498817 | O43: 4.4250305 | P43: 4.4046571e-05 | Q43: 0.59349978 | R43: 1.5746605 | S43: 0.59349978 | T43: 1.5746605
...

Sheet BetaA
B2: Regression Beta-5 yrs monthly
B4: Nifty 50 | F4: Dmart | J4: Beta Drifting | N4: Beta 1 | O4: =SLOPE(D8:D66,H8:H66) -> 0.2970684
N5: Beta 2 | O5: =N58 -> 0.2970684
B6: Date | C6: Closing Price | D6: Return | F6: Date | G6: Closing Price | H6: Return | J6: Levered Raw Beta | K6: =O4 -> 0.2970684
B7: 43831 | C7: 11962.1 | F7: 43831 | G7: 2133.95 | J7: Raw Beta Weight | K7: 0.75
B8: 43862 | C8: 11201.75 | D8: =(C8-C7)/C7 -> -0.063563254 | F8: 43862 | G8: 2323.95 | H8: =(G8-G7)/G7 -> 0.089036763
B9: 43891 | C9: 8597.75 | D9: =(C9-C8)/C8 -> -0.23246368 | F9: 43891 | G9: 2187.5 | H9: =(G9-G8)/G8 -> -0.058714688 | J9: Market Beta | K9: 1
B10: 43922 | C10: 9859.9 | D10: =(C10-C9)/C9 -> 0.14680003 | F10: 43922 | G10: 2383.65 | H10: =(G10-G9)/G9 -> 0.089668571 | J10: Market Beta Weight | K10: 0.25
B11: 43952 | C11: 9580.3 | D11: =(C11-C10)/C10 -> -0.028357286 | F11: 43952 | G11: 2269.35 | H11: =(G11-G10)/G10 -> -0.047951671
B12: 43983 | C12: 10302.1 | D12: =(C12-C11)/C11 -> 0.075342108 | F12: 43983 | G12: 2317.15 | H12: =(G12-G11)/G11 -> 0.0210633
B13: 44013 | C13: 11073.45 | D13: =(C13-C12)/C12 -> 0.074873084 | F13: 44013 | G13: 2063.45 | H13: =(G13-G12)/G12 -> -0.10948795 | J13: Adjusted Beta | K13: =K6*K7+K9*K10 -> 0.4728013
B14: 44044 | C14: 11387.5 | D14: =(C14-C13)/C13 -> 0.028360628 | F14: 44044 | G14: 2251.25 | H14: =(G14-G13)/G13 -> 0.091012624
B15: 44075 | C15: 11247.55 | D15: =(C15-C14)/C14 -> -0.012289791 | F15: 44075 | G15: 2203.15 | H15: =(G15-G14)/G14 -> -0.021365908
B16: 44105 | C16: 11642.4 | D16: =(C16-C15)/C15 -> 0.035105423 | F16: 44105 | G16: 2239.9 | H16: =(G16-G15)/G15 -> 0.016680662
B17: 44136 | C17: 12968.95 | D17: =(C17-C16)/C16 -> 0.11394128 | F17: 44136 | G17: 2289.2 | H17: =(G17-G16)/G16 -> 0.022009911
B18: 44166 | C18: 13981.75 | D18: =(C18-C17)/C17 -> 0.078094217 | F18: 44166 | G18: 2763.6 | H18: =(G18-G17)/G17 -> 0.20723397
B19: 44197 | C19: 13634.6 | D19: =(C19-C18)/C18 -> -0.024828795 | F19: 44197 | G19: 2651.5 | H19: =(G19-G18)/G18 -> -0.040563034
B20: 44228 | C20: 14529.15 | D20: =(C20-C19)/C19 -> 0.065608819 | F20: 44228 | G20: 2994.2 | H20: =(G20-G19)/G19 -> 0.1292476
B21: 44256 | C21: 14690.7 | D21: =(C21-C20)/C20 -> 0.011119026 | F21: 44256 | G21: 2859.05 | H21: =(G21-G20)/G20 -> -0.045137265
B22: 44287 | C22: 14631.1 | D22: =(C22-C21)/C21 -> -0.0040569884 | F22: 44287 | G22: 2852.9 | H22: =(G22-G21)/G21 -> -0.0021510642
B23: 44317 | C23: 15582.8 | D23: =(C23-C22)/C22 -> 0.065046374 | F23: 44317 | G23: 3069.4 | H23: =(G23-G22)/G22 -> 0.075887693
B24: 44348 | C24: 15721.5 | D24: =(C24-C23)/C23 -> 0.0089008394 | F24: 44348 | G24: 3344.1 | H24: =(G24-G23)/G23 -> 0.089496318
B25: 44378 | C25: 15763.05 | D25: =(C25-C24)/C24 -> 0.0026428776 | F25: 44378 | G25: 3500.8 | H25: =(G25-G24)/G24 -> 0.046858647
... B40: 44835 | C40: 18012.2 | D40: =(C40-C39)/C39 -> 0.053693179 | F40: 44835 | G40: 4320.9 | H40: =(G40-G39)/G39 -> -0.014966204
B41: 44866 | C41: 18758.35 | D41: =(C41-C40)/C40 -> 0.041424701 | F41: 44866 | G41: 4025.5 | H41: =(G41-G40)/G40 -> -0.068365387 | M41: SUMMARY OUTPUT
B42: 44896 | C42: 18105.3 | D42: =(C42-C41)/C41 -> -0.03481383 | F42: 44896 | G42: 4068.75 | H42: =(G42-G41)/G41 -> 0.010744007
B43: 44927 | C43: 17662.15 | D43: =(C43-C42)/C42 -> -0.024476258 | F43: 44927 | G43: 3502.3 | H43: =(G43-G42)/G42 -> -0.13921966 | M43: Regression Statistics
B44: 44958 | C44: 17303.95 | D44: =(C44-C43)/C43 -> -0.020280657 | F44: 44958 | G44: 3416.95 | H44: =(G44-G43)/G43 -> -0.0243697 | M44: Multiple R | N44: 0.45782894
B45: 44986 | C45: 17359.75 | D45: =(C45-C44)/C44 -> 0.0032246973 | F45: 44986 | G45: 3401.05 | H45: =(G45-G44)/G44 -> -0.0046532727 | M45: R Square | N45: 0.20960734
B46: 45017 | C46: 18065 | D46: =(C46-C45)/C45 -> 0.040625585 | F46: 45017 | G46: 3511.95 | H46: =(G46-G45)/G45 -> 0.032607577 | M46: Adjusted R Square | N46: 0.1957408
B47: 45047 | C47: 18534.4 | D47: =(C47-C46)/C46 -> 0.025983947 | F47: 45047 | G47: 3471.25 | H47: =(G47-G46)/G46 -> -0.011589003 | M47: Standard Error | N47: 0.048806601
B48: 45078 | C48: 19189.05 | D48: =(C48-C47)/C47 -> 0.035320809 | F48: 45078 | G48: 3889.2 | H48: =(G48-G47)/G47 -> 0.12040331 | M48: Observations | N48: 59
B49: 45108 | C49: 19753.8 | D49: =(C49-C48)/C48 -> 0.029430847 | F49: 45108 | G49: 3752.8 | H49: =(G49-G48)/G48 -> -0.03507148
B50: 45139 | C50: 19253.8 | D50: =(C50-C49)/C49 -> -0.025311586 | F50: 45139 | G50: 3720.4 | H50: =(G50-G49)/G49 -> -0.0086335536 | M50: ANOVA
B51: 45170 | C51: 19638.3 | D51: =(C51-C50)/C50 -> 0.019970084 | F51: 45170 | G51: 3675.6 | H51: =(G51-G50)/G50 -> -0.012041716 | N51: df | O51: SS | P51: MS | Q51: F | R51: Significance F
B52: 45200 | C52: 19079.6 | D52: =(C52-C51)/C51 -> -0.028449509 | F52: 45200 | G52: 3633.4 | H52: =(G52-G51)/G51 -> -0.011481119 | M52: Regression | N52: 1 | O52: 0.036007716 | P52: 0.036007716 | Q52: 15.116054 | R52: 0.00026639035
B53: 45231 | C53: 20133.15 | D53: =(C53-C52)/C52 -> 0.055218663 | F53: 45231 | G53: 3949.75 | H53: =(G53-G52)/G52 -> 0.08706721 | M53: Residual | N53: 57 | O53: 0.13577881 | P53: 0.0023820843
B54: 45261 | C54: 21731.4 | D54: =(C54-C53)/C53 -> 0.079384001 | F54: 45261 | G54: 4082.65 | H54: =(G54-G53)/G53 -> 0.033647699 | M54: Total | N54: 58 | O54: 0.17178652
B55: 45292 | C55: 21725.7 | D55: =(C55-C54)/C54 -> -0.00026229327 | F55: 45292 | G55: 3792.7 | H55: =(G55-G54)/G54 -> -0.071020048
B56: 45323 | C56: 21982.8 | D56: =(C56-C55)/C55 -> 0.011833911 | F56: 45323 | G56: 3918.9 | H56: =(G56-G55)/G55 -> 0.033274448 | N56: Coefficients | O56: Standard Error | P56: t Stat | Q56: P-value | R56: Lower 95% | S56: Upper 95% | T56: Lower 95.0% | U56: Upper 95.0%
...

Sheet Sheet7

Sheet riskpre
B2: Year | C2: Annual
B3: 2000 | C3: -0.1465
B4: 2001 | C4: -0.1618
B5: 2002 | C5: 0.0325
B6: 2003 | C6: 0.719
B7: 2004 | C7: 0.1068
B8: 2005 | C8: 0.3634
B9: 2006 | C9: 0.3983
B10: 2007 | C10: 0.5477
B11: 2008 | C11: -0.5179
B12: 2009 | C12: 0.7576
B13: 2010 | C13: 0.1795
B14: 2011 | C14: -0.2462
... B26: 2023 | C26: 0.1942
B27: 2024
B28: Average | C28: =AVERAGE(C3:C26) -> 0.15609167
B29: divend yield | C29: 1.27% 1
B30: Total return | C30: =SUM(C28:C29) -> 0.15609167

Sheet CompBeta
B2: Name | C2: CMP Rs. | D2: Mar Cap Rs.Cr. | E2: Debt Rs.Cr. | F2: Debt / Eq
B3: Avenue Super. | C3: 3816.9 | D3: 248261.6 | E3: 712.91 | F3: 0.04
B4: Trent | C4: 6878.05 | D4: 244650.38 | E4: 1842.2 | F4: 0.39
B5: Aditya Bir. Fas. | C5: 310.1 | D5: 33255.53 | E5: 9999.18 | F5: 2.44
B6: Brainbees Solut. | C6: 587.4 | D6: 30481.34 | E6: 1573.61 | F6: 0.33
B7: Redtape | C7: 821.15 | D7: 11358 | E7: 650.59 | F7: 0.92

Sheet Common size Statement
A1: c

Sheet FCFF
B1: AMU
B8: Calculation of PV og FCFF | E8: 45016 | F8: 45382 | G8: 45747 | H8: 46112 | I8: 46477 | J8: 46843
B10: EBIT | E10: =[1]historical!$H$25+[1]historical!$H$19 -> 24664.8
B11: Tax Rate | E11: 0.25 | F11: =E11 -> 0.25 | G11: =F11 -> 0.25 | H11: =G11 -> 0.25 | I11: =H11 -> 0.25 | J11: =I11 -> 0.25
B13: EBIT(1-tax) | E13: =E10*(1-E11) -> 18498.6 | F13: =F10*(1-F11) -> 0 | G13: =G10*(1-G11) -> 0 | H13: =H10*(1-H11) -> 0 | I13: =I10*(1-I11) -> 0 | J13: =J10*(1-J11) -> 0
B14: Mid Year Convention | F14: 0.5 | G14: =F14+1 -> 1.5 | H14: =G14+1 -> 2.5 | I14: =H14+1 -> 3.5 | J14: =I14+1 -> 4.5
B15: PV factor of WACC
F16: Total Cash flow
B17: Less: Reinvestment Rate
