Workbook
Name UPDATE: 'Data Sheet'!$E$1
Name UPDATE: '[1]Data Sheet'!$E$1

Sheet Key Assumption 
B2: Key Assumption and Methodology
B4: Parameter | G4: Value | H4: Rationale
B5: Valuation Date | G5: 46085
B6: Projection Period
B7: Revenue Growth | G7: 0.15 | H7: Strong Industry Growth along with International Expansion
B8: Annual Growth Tapering | G8: 0.01
B10: Terminal Growth Rate (g) | G10: 0.062 | H10: Positive Industry Growth with good gdp growth
B12: Risk-Free Rate (Rf) | G12: 0.0688 | H12: YTM of 10 yrs government bond
B13: Tax Rate | G13: 0.24 | H13: Effective Tax rate

Sheet 3 Statement model
B3: Income Statement
B4: Perticulars | E4: 2021 | F4: 2022 | G4: 2023 | H4: 2024 | I4: 2025
E5: in Cr | F5: in Cr | G5: in Cr | H5: in Cr | I5: in Cr
B7: Sales | E7: ='Data Sheet'!G17 -> 21712.79 | F7: ='Data Sheet'!H17 -> 29101.28 | G7: ='Data Sheet'!I17 -> 34488.59 | H7: ='Data Sheet'!J17 -> 35494.73 | I7: ='Data Sheet'!K17 -> 33905.62
B8: Sales Growth % | F8: =(F7/E7)-1 -> 0.34028285 | G8: =(G7/F7)-1 -> 0.18512278 | H8: =(H7/G7)-1 -> 0.029173127 | I8: =(I7/H7)-1 -> -0.044770308
B9: COGS | E9: =SUM('Data Sheet'!E18:E21) -> 12249.64 | F9: =SUM('Data Sheet'!F18:F21) -> 12282.19 | G9: =SUM('Data Sheet'!G18:G21) -> 12672.36 | H9: =SUM('Data Sheet'!H18:H21) -> 21445.9 | I9: =SUM('Data Sheet'!I18:I21) -> 22349.75
B10: COGS % Sales | E10: =E9/E7 -> 0.56416702 | F10: =F9/F7 -> 0.42204982 | G10: =G9/G7 -> 0.3674363 | H10: =H9/H7 -> 0.60419955 | I10: =I9/I7 -> 0.65917538
B11: Gross Profit | E11: =E7-E9 -> 9463.15 | F11: =F7-F9 -> 16819.09 | G11: =G7-G9 -> 21816.23 | H11: =H7-H9 -> 14048.83 | I11: =I7-I9 -> 11555.87
B12: Gross Profit % Sale | E12: =E11/E7 -> 0.43583298 | F12: =F11/F7 -> 0.57795018 | G12: =G11/G7 -> 0.6325637 | H12: =H11/H7 -> 0.39580045 | I12: =I11/I7 -> 0.34082462
B13: Other Expenses | E13: =SUM('Data Sheet'!G22:G24) -> 4369.73 | F13: =SUM('Data Sheet'!H22:H24) -> 5501.71 | G13: =SUM('Data Sheet'!I22:I24) -> 6498.46 | H13: =SUM('Data Sheet'!J22:J24) -> 7234.68 | I13: =SUM('Data Sheet'!K22:K24) -> 7763.92
B14: Other Expenses % Sales | E14: =E13/E7 -> 0.20125143 | F14: =F13/F7 -> 0.18905388 | G14: =G13/G7 -> 0.18842348 | H14: =H13/H7 -> 0.20382406 | I14: =I13/I7 -> 0.22898623
B15: EBITDA | E15: =E11-E13 -> 5093.42 | F15: =F11-F13 -> 11317.38 | G15: =G11-G13 -> 15317.77 | H15: =H11-H13 -> 6814.15 | I15: =I11-I13 -> 3791.95
B16: EBITDA % SALES | E16: =E15/E7 -> 0.23458155 | F16: =F15/F7 -> 0.3888963 | G16: =G15/G7 -> 0.44414022 | H16: =H15/H7 -> 0.19197639 | I16: =I15/I7 -> 0.11183839
B17: Depriciation | E17: ='Data Sheet'!G26 -> 791.27 | F17: ='Data Sheet'!H26 -> 816.36 | G17: ='Data Sheet'!I26 -> 858.02 | H17: ='Data Sheet'!J26 -> 853 | I17: ='Data Sheet'!K26 -> 1026.34
B18: Depriciation % Sales | E18: =E17/E7 -> 0.036442576 | F18: =F17/F7 -> 0.028052374 | G18: =G17/G7 -> 0.024878373 | H18: =H17/H7 -> 0.024031737 | I18: =I17/I7 -> 0.030270498
B19: EBIT | E19: =E15-E17 -> 4302.15 | F19: =F15-F17 -> 10501.02 | G19: =G15-G17 -> 14459.75 | H19: =H15-H17 -> 5961.15 | I19: =I15-I17 -> 2765.61
B20: EBIT % sales | E20: =E19/E7 -> 0.19813898 | F20: =F19/F7 -> 0.36084392 | G20: =G19/G7 -> 0.41926185 | H20: =H19/H7 -> 0.16794465 | I20: =I19/I7 -> 0.081567893
B21: Other Income | E21: ='Data Sheet'!G25 -> 331.65 | F21: ='Data Sheet'!H25 -> 295.88 | G21: ='Data Sheet'!I25 -> 431.46 | H21: ='Data Sheet'!J25 -> 820.96 | I21: ='Data Sheet'!K25 -> 350.22
B22: Interest | E22: ='Data Sheet'!G27 -> 91.63 | F22: ='Data Sheet'!H27 -> 95.41 | G22: ='Data Sheet'!I27 -> 144.45 | H22: ='Data Sheet'!J27 -> 205.17 | I22: ='Data Sheet'!K27 -> 227.02
B23: % of debt | E23: =E22/'Data Sheet'!G59 -> 0.083824283 | F23: =F22/'Data Sheet'!H59 -> 0.060124269 | G23: =G22/'Data Sheet'!I59 -> 0.074743095 | H23: =H22/'Data Sheet'!J59 -> 0.082917741 | I23: =I22/'Data Sheet'!K59 -> 0.099122819
B24: EBT | E24: =E19+E21-E22 -> 4542.17 | F24: =F19+F21-F22 -> 10701.49 | G24: =G19+G21-G22 -> 14746.76 | H24: =H19+H21-H22 -> 6576.94 | I24: =I19+I21-I22 -> 2888.81
B25: EBT % sale | E25: =E24/E7 -> 0.20919329 | F25: =F24/F7 -> 0.36773262 | G25: =G24/G7 -> 0.42758373 | H25: =H24/H7 -> 0.18529342 | I25: =I24/I7 -> 0.085201509
B26: Tax | E26: ='Data Sheet'!G29 -> 1097.6 | F26: ='Data Sheet'!H29 -> 1102.91 | G26: ='Data Sheet'!I29 -> 1493.5 | H26: ='Data Sheet'!J29 -> 1790.08 | I26: ='Data Sheet'!K29 -> 1393.36
B27: Effective Tax Rate | E27: =E26/E24 -> 0.24164661 | F27: =F26/F24 -> 0.10306135 | G27: =G26/G24 -> 0.10127648 | H27: =H26/H24 -> 0.27217521 | I27: =I26/I24 -> 0.48233009
B28: Net Profit | E28: =E24-E26 -> 3444.57 | F28: =F24-F26 -> 9598.58 | G28: =G24-G26 -> 13253.26 | H28: =H24-H26 -> 4786.86 | I28: =I24-I26 -> 1495.45
B34: Balance Sheet
B35: Perticular | E35: =E4 -> 2021 | F35: =F4 -> 2022 | G35: =G4 -> 2023 | H35: =H4 -> 2024 | I35: =I4 -> 2025
B36: Liabilities
B37: Equity Share Capital | E37: ='Data Sheet'!G57 -> 95.92 | F37: ='Data Sheet'!H57 -> 95.92 | G37: ='Data Sheet'!I57 -> 95.92 | H37: ='Data Sheet'!J57 -> 95.92 | I37: ='Data Sheet'!K57 -> 95.92
B38: Reserves | E38: ='Data Sheet'!G58 -> 12710.37 | F38: ='Data Sheet'!H58 -> 13715.64 | G38: ='Data Sheet'!I58 -> 15896.31 | H38: ='Data Sheet'!J58 -> 18632.38 | I38: ='Data Sheet'!K58 -> 19303.89
B39: Borrowings | E39: ='Data Sheet'!G59 -> 1093.12 | F39: ='Data Sheet'!H59 -> 1586.88 | G39: ='Data Sheet'!I59 -> 1932.62 | H39: ='Data Sheet'!J59 -> 2474.38 | I39: ='Data Sheet'!K59 -> 2290.29
B40: Other Liabilities | E40: ='Data Sheet'!G60 -> 6455.93 | F40: ='Data Sheet'!H60 -> 7559.99 | G40: ='Data Sheet'!I60 -> 7854.48 | H40: ='Data Sheet'!J60 -> 8698.09 | I40: ='Data Sheet'!K60 -> 8665.15
B41: Total Liabilities | E41: =SUM(E37:E40) -> 20355.34 | F41: =SUM(F37:F40) -> 22958.43 | G41: =SUM(G37:G40) -> 25779.33 | H41: =SUM(H37:H40) -> 29900.77 | I41: =SUM(I37:I40) -> 30355.25
B43: Assets
B44: Net Block | E44: ='Data Sheet'!G62 -> 5858.52 | F44: ='Data Sheet'!H62 -> 5519.06 | G44: ='Data Sheet'!I62 -> 5770.46 | H44: ='Data Sheet'!J62 -> 7146.62 | I44: ='Data Sheet'!K62 -> 9220.1
B45: Capital Work in Progress | E45: ='Data Sheet'!G63 -> 182.98 | F45: ='Data Sheet'!H63 -> 426.43 | G45: ='Data Sheet'!I63 -> 1019.59 | H45: ='Data Sheet'!J63 -> 2698.37 | I45: ='Data Sheet'!K63 -> 1254.49
B46: Investments | E46: ='Data Sheet'!G64 -> 4736.8 | F46: ='Data Sheet'!H64 -> 3247.53 | G46: ='Data Sheet'!I64 -> 4261.71 | H46: ='Data Sheet'!J64 -> 4587.92 | I46: ='Data Sheet'!K64 -> 4724.75
B47: Receivables | E47: ='Data Sheet'!G67 -> 2602.17 | F47: ='Data Sheet'!H67 -> 3871.44 | G47: ='Data Sheet'!I67 -> 4636.94 | H47: ='Data Sheet'!J67 -> 4889.05 | I47: ='Data Sheet'!K67 -> 4313.65
B48: Inventory | E48: ='Data Sheet'!G68 -> 3798.6 | F48: ='Data Sheet'!H68 -> 6152.98 | G48: ='Data Sheet'!I68 -> 6210.64 | H48: ='Data Sheet'!J68 -> 5923.41 | I48: ='Data Sheet'!K68 -> 6719.27
B49: Cash & Bank | E49: ='Data Sheet'!G69 -> 610.75 | F49: ='Data Sheet'!H69 -> 864.33 | G49: ='Data Sheet'!I69 -> 843.82 | H49: ='Data Sheet'!J69 -> 1084.01 | I49: ='Data Sheet'!K69 -> 781.98
...

Sheet Revenue Growth and Assumption
B2: Revenue Growth and Assumptions
B3: Year | E3: 2026 | F3: 2027 | G3: 2028 | H3: 2029 | I3: 2030
B4: Revenue Growth % | E4: =CHOOSE($F$6,E7:I7,E8:I8,E9:I9) -> 0.15 | F4: =CHOOSE($F$6,F7:J7,F8:J8,F9:J9) -> 0.14 | G4: =CHOOSE($F$6,G7:K7,G8:K8,G9:K9) -> 0.13 | H4: =CHOOSE($F$6,H7:L7,H8:L8,H9:L9) -> 0.12 | I4: =CHOOSE($F$6,I7:M7,I8:M8,I9:M9) -> 0.11
B5: Revenue (in Crs.) | E5: ='3 Statement model'!$I$7*(1+'Revenue Growth and Assumption'!E4) -> 38991.463 | F5: ='3 Statement model'!$I$7*(1+'Revenue Growth and Assumption'!F4) -> 38652.407 | G5: ='3 Statement model'!$I$7*(1+'Revenue Growth and Assumption'!G4) -> 38313.351 | H5: ='3 Statement model'!$I$7*(1+'Revenue Growth and Assumption'!H4) -> 37974.294 | I5: ='3 Statement model'!$I$7*(1+'Revenue Growth and Assumption'!I4) -> 37635.238
B6: Choosen Scenario | E6: Base Case | F6: =MATCH(E6,B7:B9,) -> 1
B7: Base Case | E7: ='Key Assumption '!G7 -> 0.15 | F7: =E7-'Key Assumption '!$G$8 -> 0.14 | G7: =F7-'Key Assumption '!$G$8 -> 0.13 | H7: =G7-'Key Assumption '!$G$8 -> 0.12 | I7: =H7-'Key Assumption '!$G$8 -> 0.11
B8: Best Case | E8: ='Key Assumption '!G7+5% -> 0.2 | F8: =E8-'Key Assumption '!$G$8 -> 0.19 | G8: =F8-'Key Assumption '!$G$8 -> 0.18 | H8: =G8-'Key Assumption '!$G$8 -> 0.17 | I8: =H8-'Key Assumption '!$G$8 -> 0.16
B9: Worst Case | E9: ='Key Assumption '!G7-2% -> 0.13 | F9: =E9-'Key Assumption '!$G$8 -> 0.12 | G9: =F9-'Key Assumption '!$G$8 -> 0.11 | H9: =G9-'Key Assumption '!$G$8 -> 0.1 | I9: =H9-'Key Assumption '!$G$8 -> 0.09

Sheet Beta
B3: Beta Calcutaion
C4: Asian Paints | F4: Nifty 50 | I4: BERGER | L4: Kane Nerolac | O4: Akzo Nobel | R4: Indigo Paints
B6: Date | C6: Price | D6: Change % | F6: Price | G6: Change % | I6: Price | J6: Change % | L6: Price | M6: Change % | O6: Price | P6: Change % | R6: Price | S6: Change %
B7: 46082 | C7: 2279.5 | D7: =(C7/C8)-1 -> -0.040695228 | F7: 24450.45 | G7: =(F7/F8)-1 -> -0.028921328 | I7: 440.3 | J7: =LN(I7/I8) -> -0.035255771 | L7: 189.19 | M7: =(L7/L8)-1 -> -0.070365093 | O7: 2774.8 | P7: =(O7/O8)-1 -> -0.054679249 | R7: 873.5 | S7: =(R7/R8)-1 -> -0.067570453
B8: 46075 | C8: 2376.2 | D8: =(C8/C9)-1 -> -0.021374737 | F8: 25178.65 | G8: =(F8/F9)-1 -> -0.01535318 | I8: 456.1 | J8: =LN(I8/I9) -> 0.0014261425 | L8: 203.51 | M8: =(L8/L9)-1 -> 0.024258896 | O8: 2935.3 | P8: =(O8/O9)-1 -> -0.038992928 | R8: 936.8 | S8: =(R8/R9)-1 -> -0.0076271186
B9: 46068 | C9: 2428.1 | D9: =(C9/C10)-1 -> 0.02607336 | F9: 25571.25 | G9: =(F9/F10)-1 -> 0.0039319071 | I9: 455.45 | J9: =LN(I9/I10) -> -0.01427895 | L9: 198.69 | M9: =(L9/L10)-1 -> -0.0066989952 | O9: 3054.4 | P9: =(O9/O10)-1 -> 0.035074045 | R9: 944 | S9: =(R9/R10)-1 -> -0.029904429
B10: 46061 | C10: 2366.4 | D10: =(C10/C11)-1 -> -0.01445171 | F10: 25471.1 | G10: =(F10/F11)-1 -> -0.0086636024 | I10: 462 | J10: =LN(I10/I11) -> -0.022261193 | L10: 200.03 | M10: =(L10/L11)-1 -> -0.066806625 | O10: 2950.9 | P10: =(O10/O11)-1 -> 0.01106695 | R10: 973.1 | S10: =(R10/R11)-1 -> -0.035484191
B11: 46054 | C11: 2401.1 | D11: =(C11/C12)-1 -> -0.011201252 | F11: 25693.7 | G11: =(F11/F12)-1 -> 0.014733034 | I11: 472.4 | J11: =LN(I11/I12) -> 0.020315036 | L11: 214.35 | M11: =(L11/L12)-1 -> -0.06881272 | O11: 2918.6 | P11: =(O11/O12)-1 -> 0.042357143 | R11: 1008.9 | S11: =(R11/R12)-1 -> -0.033990808
B12: 46047 | C12: 2428.3 | D12: =(C12/C13)-1 -> -0.10186041 | F12: 25320.65 | G12: =(F12/F13)-1 -> 0.010858869 | I12: 462.9 | J12: =LN(I12/I13) -> -0.086056792 | L12: 230.19 | M12: =(L12/L13)-1 -> 0.013695614 | O12: 2800 | P12: =(O12/O13)-1 -> -0.047165317 | R12: 1044.4 | S12: =(R12/R13)-1 -> -0.0029594272
B13: 46040 | C13: 2703.7 | D13: =(C13/C14)-1 -> -0.019297037 | F13: 25048.65 | G13: =(F13/F14)-1 -> -0.025130038 | I13: 504.5 | J13: =LN(I13/I14) -> -0.029780087 | L13: 227.08 | M13: =(L13/L14)-1 -> -0.01879618 | O13: 2938.6 | P13: =(O13/O14)-1 -> -0.048627299 | R13: 1047.5 | S13: =(R13/R14)-1 -> -0.15278227
B14: 46033 | C14: 2756.9 | D14: =(C14/C15)-1 -> -0.024278889 | F14: 25694.35 | G14: =(F14/F15)-1 -> 0.00043024066 | I14: 519.75 | J14: =LN(I14/I15) -> 0.010735632 | L14: 231.43 | M14: =(L14/L15)-1 -> -0.0044308698 | O14: 3088.8 | P14: =(O14/O15)-1 -> -0.014391014 | R14: 1236.4 | S14: =(R14/R15)-1 -> 0.030075814
B15: 46026 | C15: 2825.5 | D15: =(C15/C16)-1 -> 0.019079564 | F15: 25683.3 | G15: =(F15/F16)-1 -> -0.024507616 | I15: 514.2 | J15: =LN(I15/I16) -> -0.019070211 | L15: 232.46 | M15: =(L15/L16)-1 -> -0.035755766 | O15: 3133.9 | P15: =(O15/O16)-1 -> -0.024193548 | R15: 1200.3 | S15: =(R15/R16)-1 -> 0.024846311
B16: 46019 | C16: 2772.6 | D16: =(C16/C17)-1 -> 0.0095030038 | F16: 26328.55 | G16: =(F16/F17)-1 -> 0.010991733 | I16: 524.1 | J16: =LN(I16/I17) -> -0.033675742 | L16: 241.08 | M16: =(L16/L17)-1 -> 0.015415719 | O16: 3211.6 | P16: =(O16/O17)-1 -> 0.028106793 | R16: 1171.2 | S16: =(R16/R17)-1 -> 0.038758315
B17: 46012 | C17: 2746.5 | D17: =(C17/C18)-1 -> -0.01907211 | F17: 26042.3 | G17: =(F17/F18)-1 -> 0.0029230082 | I17: 542.05 | J17: =LN(I17/I18) -> 0.0074996879 | L17: 237.42 | M17: =(L17/L18)-1 -> 0.064759171 | O17: 3123.8 | P17: =(O17/O18)-1 -> -0.0081285324 | R17: 1127.5 | S17: =(R17/R18)-1 -> -0.051405014
B18: 46005 | C18: 2799.9 | D18: =(C18/C19)-1 -> 0.012695312 | F18: 25966.4 | G18: =(F18/F19)-1 -> -0.0030924926 | I18: 538 | J18: =LN(I18/I19) -> -0.0060227192 | L18: 222.98 | M18: =(L18/L19)-1 -> -0.0023266219 | O18: 3149.4 | P18: =(O18/O19)-1 -> -0.12545818 | R18: 1188.6 | S18: =(R18/R19)-1 -> -0.036712862
... B270: 44241 | C270: 2416.45 | D270: =(C270/C271)-1 -> -0.028015768 | F270: 14981.75 | G270: =(F270/F271)-1 -> -0.011972987 | I270: 617.71 | J270: =LN(I270/I271) -> -0.038506905 | L270: 371.95 | M270: =(L270/L271)-1 -> -0.022264865 | O270: 2146.55 | P270: =(O270/O271)-1 -> -0.02127029 | R270: 2572.6 | S270: =(R270/R271)-1 -> -0.014612659
B271: 44234 | C271: 2486.1 | F271: 15163.3 | I271: 641.96 | L271: 380.42 | O271: 2193.2 | R271: 2610.75
B274: Beta
B276: Asian Paints | C276: =SLOPE(D7:D270,$G$7:$G$270) -> 0.88936432 | I276: Berger | J276: =SLOPE(J7:J270,G7:G270) -> 0.89286828 | L276: kane nerolac | M276: =SLOPE(M7:M270,G7:G270) -> 0.844251 | O276: Akzo nobel | P276: =SLOPE(P7:P270,G7:G270) -> 0.5265612 | R276: Indigo | S276: =SLOPE(S7:S270,G7:G270) -> 0.77568817

Sheet WACC
B2: WACC Calculation
B4: Target Capital Structure
B5: Proportion of Debt | L5: =Comp!H18 -> 0.035
B6: Proportion of Equity | L6: =1-L5 -> 0.965
B7: Actual Capital Structure
B8: Market Cap | L8: =Comp!E4 -> 219402.07
B9: Total Debt | L9: =Comp!F4 -> 3557.09
B10: Debt to Equity Ratio | L10: =L9/L8 -> 0.016212655
B11: Cost of Debt
B12: Pre-Tax Cost of Debt | L12: 0.07
B13: Tax Rate | L13: ='Key Assumption '!G13 -> 0.24
B14: After-Tax Cost of Debt | L14: =L12*(1-L13) -> 0.0532
B15: Cost of equity
B16: Risk Free Rate(Rf) | L16: ='Key Assumption '!G12 -> 0.0688
B17: Beta | L17: =Comp!L18 -> 0.79170861
B18: Rate of Return of Market | L18: =0.13 -> 0.13
B19: ERP | L19: =L18-L16 -> 0.0612
B20: Cost of Equity | L20: =L16+L17*(L19) -> 0.11725257
B21: WACC | L21: =L5*L14+L20*L6 -> 0.11501073

Sheet DCF Modelling
B2: Free Cash Flow to Firm (FCFF) Calcutaion
B6: Years | F6: 2026 | G6: 2027 | H6: 2028 | I6: 2029 | J6: 2030
B8: Time Periods | F8: 1 | G8: 2 | H8: 3 | I8: 4 | J8: 5
B9: Year Fraction
B10: Revenue | F10: ='Revenue Growth and Assumption'!E5 -> 38991.463 | G10: ='Revenue Growth and Assumption'!F5 -> 38652.407 | H10: ='Revenue Growth and Assumption'!G5 -> 38313.351 | I10: ='Revenue Growth and Assumption'!H5 -> 37974.294 | J10: ='Revenue Growth and Assumption'!I5 -> 37635.238
B11: EBITDA Margin % | F11: =MEDIAN('3 Statement model'!$E$16:$I$16) -> 0.23458155 | G11: =MEDIAN('3 Statement model'!$E$16:$I$16) -> 0.23458155 | H11: =MEDIAN('3 Statement model'!$E$16:$I$16) -> 0.23458155 | I11: =MEDIAN('3 Statement model'!$E$16:$I$16) -> 0.23458155 | J11: =MEDIAN('3 Statement model'!$E$16:$I$16) -> 0.23458155
B12: EBITDA | F12: =F10*F11 -> 9146.6779 | G12: =G10*G11 -> 9067.1416 | H12: =H10*H11 -> 8987.6053 | I12: =I10*I11 -> 8908.069 | J12: =J10*J11 -> 8828.5326
B13: less: Depriciation | F13: =F$10*AVERAGE('3 Statement model'!$F$18:$J$18) -> 1045.2927 | G13: =G$10*AVERAGE('3 Statement model'!$F$18:$J$18) -> 1036.2032 | H13: =H$10*AVERAGE('3 Statement model'!$F$18:$J$18) -> 1027.1137 | I13: =I$10*AVERAGE('3 Statement model'!$F$18:$J$18) -> 1018.0242 | J13: =J$10*AVERAGE('3 Statement model'!$F$18:$J$18) -> 1008.9347
B14: EBIT | F14: =F12-F13 -> 8101.3852 | G14: =G12-G13 -> 8030.9384 | H14: =H12-H13 -> 7960.4916 | I14: =I12-I13 -> 7890.0448 | J14: =J12-J13 -> 7819.5979
B15: Less: Cash Taxes | F15: =F14*'Key Assumption '!$G$13 -> 1944.3325 | G15: =G14*'Key Assumption '!$G$13 -> 1927.4252 | H15: =H14*'Key Assumption '!$G$13 -> 1910.518 | I15: =I14*'Key Assumption '!$G$13 -> 1893.6107 | J15: =J14*'Key Assumption '!$G$13 -> 1876.7035
B16: NOPAT | F16: =F14-F15 -> 6157.0528 | G16: =G14-G15 -> 6103.5132 | H16: =H14-H15 -> 6049.9736 | I16: =I14-I15 -> 5996.434 | J16: =J14-J15 -> 5942.8944
B17: Plus: D&A | F17: =F13 -> 1045.2927 | G17: =G13 -> 1036.2032 | H17: =H13 -> 1027.1137 | I17: =I13 -> 1018.0242 | J17: =J13 -> 1008.9347
B18: Less: Capex | F18: =MEDIAN('Data Sheet'!$G$87:$K$87)*('DCF Modelling'!F16) -> -1017.8917 | G18: =MEDIAN('Data Sheet'!$G$87:$K$87)*('DCF Modelling'!G16) -> -1009.0405 | H18: =MEDIAN('Data Sheet'!$G$87:$K$87)*('DCF Modelling'!H16) -> -1000.1892 | I18: =MEDIAN('Data Sheet'!$G$87:$K$87)*('DCF Modelling'!I16) -> -991.338 | J18: =MEDIAN('Data Sheet'!$G$87:$K$87)*('DCF Modelling'!J16) -> -982.48677
B19: Less: Changes in NWC | F19: =AVERAGE('Data Sheet'!$G$76:$K$76)*'DCF Modelling'!F$16 -> -1228.8439 | G19: =AVERAGE('Data Sheet'!$G$76:$K$76)*'DCF Modelling'!G$16 -> -1218.1583 | H19: =AVERAGE('Data Sheet'!$G$76:$K$76)*'DCF Modelling'!H$16 -> -1207.4727 | I19: =AVERAGE('Data Sheet'!$G$76:$K$76)*'DCF Modelling'!I$16 -> -1196.7871 | J19: =AVERAGE('Data Sheet'!$G$76:$K$76)*'DCF Modelling'!J$16 -> -1186.1015
B20: Unlevered FCF | F20: =SUM(F16:F19) -> 4955.6099 | G20: =SUM(G16:G19) -> 4912.5176 | H20: =SUM(H16:H19) -> 4869.4254 | I20: =SUM(I16:I19) -> 4826.3331 | J20: =SUM(J16:J19) -> 4783.2408
B22: Terminal Value Calculation
B25: Terminal Year FCF(2030) | F25: =J20 -> 4783.2408
B26: Terminal Growth Rate(g) | F26: ='Key Assumption '!G10 -> 0.062
B28: Terminal Value | F28: =F25*(1+F26)/(WACC!L21-'DCF Modelling'!F26) -> 95825.922
B31: Present Value Calculation
B34: Years | F34: =F6 -> 2026 | G34: =G6 -> 2027 | H34: =H6 -> 2028 | I34: =I6 -> 2029 | J34: =J6 -> 2030 | K34: =B28 -> Terminal Value
B35: FCF (in Crs.) | F35: =F20 -> 4955.6099 | G35: =G20 -> 4912.5176 | H35: =H20 -> 4869.4254 | I35: =I20 -> 4826.3331 | J35: =J20 -> 4783.2408 | K35: =F28 -> 95825.922
B36: Discounting Factor | F36: =WACC!$L$21 -> 0.11501073 | G36: =WACC!$L$21 -> 0.11501073 | H36: =WACC!$L$21 -> 0.11501073 | I36: =WACC!$L$21 -> 0.11501073 | J36: =WACC!$L$21 -> 0.11501073 | K36: =WACC!$L$21 -> 0.11501073
B37: PV of FCFF | F37: =F35/(1+F36)^F8 -> 4444.4504 | G37: =G35/(1+G36)^G8 -> 3951.3548 | H37: =H35/(1+H36)^H8 -> 3512.6961 | I37: =I35/(1+I36)^I8 -> 3122.4904 | J37: =J35/(1+J36)^J8 -> 2775.4092 | K37: =K35/(1+K36)^5 -> 55601.663
B40: DCF Valuation Summary
B43: Sum of PV of FCFF(2026-2030) | F43: PV of Terminal Value | J43: EV Value of Firm
B45: =SUM(F37:J37) -> 17806.401 | F45: =K37 -> 55601.663 | J45: =SUM(B44:I45) -> 73408.064
B47: EV Value | H47: =J45 -> 73408.064
B48: Less: Net Debt | H48: =WACC!L9 -> 3557.09
B49: Add: Cash and Equivalent | H49: ='Data Sheet'!K69 -> 781.98
B50: Equity Value | H50: =H47-H48+H49 -> 70632.954
B51: Share Outstanding | H51: ='Data Sheet'!K93 -> 95.92
B52: Fair Value per Share | H52: =H50/H51 -> 736.37358
B53: Current Market Price | H53: =Comp!D4 -> 2287.8
B54: Upside/Downside | H54: =(H52/H53)-1 -> -0.67813027
B57: Sensitivity Analysis
B58: Terminal Growth / WACC | E58: =WACC!L21 -> 0.11501073 | F58: ='Key Assumption '!G10 -> 0.062
B59: =H52 -> 736.37358 | C59: =D59-1% -> 0.085010727 | D59: =E59-1% -> 0.095010727 | E59: =F59-1% -> 0.10501073 | F59: =WACC!L21 -> 0.11501073 | G59: =F59+1% -> 0.12501073 | H59: =G59+1% -> 0.13501073 | I59: =H59+1% -> 0.14501073
B60: =B61-1% -> 0.042 | C60: 736.37358 | D60: 736.37358 | E60: 736.37358 | F60: 736.37358 | G60: 736.37358 | H60: 736.37358 | I60: 736.37358
B61: =B62-1% -> 0.052 | C61: 736.37358 | D61: 736.37358 | E61: 736.37358 | F61: 736.37358 | G61: 736.37358 | H61: 736.37358 | I61: 736.37358
...

Sheet Comp
B2: Comps Data
C3: Name | D3: CMP Rs. | E3: Mar Cap Rs.Cr. | F3: Debt Rs.Cr. | G3: Debt / Eq | H3: EV Rs.Cr. | I3: EV / EBITDA | J3: P/E | K3: No. of Share Holders | L3: Eq Cap Rs.Cr. | M3: Sales Rs.Cr. | N3: Beta | O3: Net Profit | P3: EPS | Q3: Cash and Equivalents
B4: 1 | C4: Asian Paints | D4: 2287.8 | E4: 219402.07 | F4: 3557.09 | G4: 0.18 | H4: 221948.49 | I4: 30.99 | J4: 53.77 | K4: 1000999 | L4: 95.92 | M4: 34695.75 | N4: =E13 -> 0.89286828 | O4: 3910.03 | P4: 40.09 | Q4: 1010.67
B5: 2 | C5: Berger Paints | D5: 434.8 | E5: 50725.12 | F5: 697.33 | G5: 0.11 | H5: 50972.62 | I5: 26.4 | J5: 45.27 | K5: 323008 | L5: 116.6 | M5: 11716.25 | N5: =E13 -> 0.89286828 | O5: 1055.68 | P5: 9.04 | Q5: 449.83
B6: 3 | C6: Kansai Nerolac | D6: 193.38 | E6: 15653.72 | F6: 276.42 | G6: 0.04 | H6: 15662.83 | I6: 14.54 | J6: 25.34 | K6: 151213 | L6: 80.85 | M6: 7914.85 | N6: =E14 -> 0.844251 | O6: 568.38 | P6: 7.24 | Q6: 267.31
B7: 4 | C7: Akzo Nobel | D7: 2835.5 | E7: 12923.89 | F7: 71.2 | G7: 0.03 | H7: 12721.09 | I7: 22.17 | J7: 34.33 | K7: 50314 | L7: 45.5 | M7: 3759.8 | N7: =E15 -> 0.5265612 | O7: 1955.3 | P7: 429.36 | Q7: 274
B8: 5 | C8: Indigo Paints | D8: 900.3 | E8: 4305.51 | F8: 17.64 | G8: 0.02 | H8: 4314.06 | I8: 16.69 | J8: 28.87 | K8: 142630 | L8: 47.68 | M8: 1299.42 | N8: =E16 -> 0.77568817 | O8: 144.95 | P8: 30.42 | Q8: 9.09
B11: Industry Beta
C12: Name | E12: Beta | F12: Equity Value | G12: Total debt | H12: Debt / Eq | I12: Debt / capital | J12: Tax rate | K12: Levered Beta | L12: Unlevered Beta
B13: 1 | C13: Berger Paints | E13: =Beta!J276 -> 0.89286828 | F13: =E5 -> 50725.12 | G13: =F5 -> 697.33 | H13: =G5 -> 0.11 | I13: =G13/(F13+G13) -> 0.013560809 | J13: ='Key Assumption '!$G$13 -> 0.24 | K13: =E13 -> 0.89286828 | L13: =K13/(1+(1-J13)*H13) -> 0.82398328
B14: 2 | C14: Kansai Nerolac | E14: =Beta!M276 -> 0.844251 | F14: =E6 -> 15653.72 | G14: =F6 -> 276.42 | H14: =G6 -> 0.04 | I14: =G14/(F14+G14) -> 0.017352013 | J14: ='Key Assumption '!$G$13 -> 0.24 | K14: =E14 -> 0.844251 | L14: =K14/(1+(1-J14)*H14) -> 0.81934297
B15: 3 | C15: Akzo Nobel | E15: =Beta!P276 -> 0.5265612 | F15: =E7 -> 12923.89 | G15: =F7 -> 71.2 | H15: =G7 -> 0.03 | I15: =G15/(F15+G15) -> 0.0054789925 | J15: ='Key Assumption '!$G$13 -> 0.24 | K15: =E15 -> 0.5265612 | L15: =K15/(1+(1-J15)*H15) -> 0.51482323
B16: 4 | C16: Indigo Paints | E16: =Beta!S276 -> 0.77568817 | F16: =E8 -> 4305.51 | G16: =F8 -> 17.64 | H16: =G8 -> 0.02 | I16: =G16/(F16+G16) -> 0.0040803581 | J16: ='Key Assumption '!$G$13 -> 0.24 | K16: =E16 -> 0.77568817 | L16: =K16/(1+(1-J16)*H16) -> 0.76407424
C17: Average | H17: =AVERAGE(H13:H16) -> 0.05 | I17: =AVERAGE(I13:I16) -> 0.010118043 | J17: =AVERAGE(J13:J16) -> 0.24 | K17: =AVERAGE(K13:K16) -> 0.75984216 | L17: =AVERAGE(L13:L16) -> 0.73055593
C18: Median | H18: =MEDIAN(H13:H16) -> 0.035 | I18: =MEDIAN(I13:I16) -> 0.0095199005 | J18: =MEDIAN(J13:J16) -> 0.24 | K18: =MEDIAN(K13:K16) -> 0.80996958 | L18: =MEDIAN(L13:L16) -> 0.79170861
B21: Comparable Company Analysis
C22: Name | D22: Ticker | E22: Price | F22: Share | G22: Market Cap | H22: Debt | I22: Enterprise value | J22: EBITDA | K22: Sales | L22: Earning | M22: EV/EBITDA | N22: EV/SALES | O22: P/E
B23: 1 | C23: Asian Paints | E23: =D4 -> 2287.8 | F23: =K4 -> 1000999 | G23: =E4 -> 219402.07 | H23: =F4 -> 3557.09 | I23: =G23+H23-Q4 -> 221948.49 | J23: =I23/M23 -> 7161.939 | K23: =M4 -> 34695.75 | L23: =O4 -> 3910.03 | M23: =I4 -> 30.99 | N23: =I23/K23 -> 6.3969936 | O23: =G23/L23 -> 56.112631
B24: 2 | C24: Berger Paints | E24: =D5 -> 434.8 | F24: =K5 -> 323008 | G24: =E5 -> 50725.12 | H24: =F5 -> 697.33 | I24: =G24+H24-Q5 -> 50972.62 | J24: =I24/M24 -> 1930.7811 | K24: =M5 -> 11716.25 | L24: =O5 -> 1055.68 | M24: =I5 -> 26.4 | N24: =I24/K24 -> 4.3505917 | O24: =G24/L24 -> 48.049712
B25: 3 | C25: Kansai Nerolac | E25: =D6 -> 193.38 | F25: =K6 -> 151213 | G25: =E6 -> 15653.72 | H25: =F6 -> 276.42 | I25: =G25+H25-Q6 -> 15662.83 | J25: =I25/M25 -> 1077.2235 | K25: =M6 -> 7914.85 | L25: =O6 -> 568.38 | M25: =I6 -> 14.54 | N25: =I25/K25 -> 1.9789168 | O25: =G25/L25 -> 27.540941
B26: 4 | C26: Akzo Nobel | E26: =D7 -> 2835.5 | F26: =K7 -> 50314 | G26: =E7 -> 12923.89 | H26: =F7 -> 71.2 | I26: =G26+H26-Q7 -> 12721.09 | J26: =I26/M26 -> 573.79747 | K26: =M7 -> 3759.8 | L26: =O7 -> 1955.3 | M26: =I7 -> 22.17 | N26: =I26/K26 -> 3.3834486 | O26: =G26/L26 -> 6.6096712
B27: 5 | C27: Indigo Paints | E27: =D8 -> 900.3 | F27: =K8 -> 142630 | G27: =E8 -> 4305.51 | H27: =F8 -> 17.64 | I27: =G27+H27-Q8 -> 4314.06 | J27: =I27/M27 -> 258.48173 | K27: =M8 -> 1299.42 | L27: =O8 -> 144.95 | M27: =I8 -> 16.69 | N27: =I27/K27 -> 3.3199889 | O27: =G27/L27 -> 29.703415
C29: Average | M29: =AVERAGE(M23:M27) -> 22.158 | N29: =AVERAGE(N23:N27) -> 3.8859879 | O29: =AVERAGE(O23:O27) -> 33.603274
C30: Median | M30: =MEDIAN(M23:M27) -> 22.17 | N30: =MEDIAN(N23:N27) -> 3.3834486 | O30: =MEDIAN(O23:O27) -> 29.703415

Sheet Ratio Analysis
B3: Sales Growth
B4: Gross Margin
B5: EBITDA Growth
B6: EBIT Growth
B7: Net Profit Growth
B8: Dividend Growth
B10: Gross Margin
B11: Operating Margin
B12: EBITDA Margin
B13: EBIT Margin
B14: EBT Margin
B15: Net Profit Margin
... B41: CFO/Total Debt

Sheet Data Sheet
A1: COMPANY NAME | B1: ASIAN PAINTS LTD | E1: ASIAN PAINTS LTD
A2: LATEST VERSION | B2: 2.1 | E2: PLEASE DO NOT MAKE ANY CHANGES TO THIS SHEET
A3: CURRENT VERSION | B3: 2.1
A5: META
A6: Number of shares | B6: =IF(B9>0, B9/B8, 0) -> 95.917763
A7: Face Value | B7: 1
A8: Current Price | B8: 2307.1
A9: Market Capitalization | B9: 221291.87
A15: PROFIT & LOSS
A16: Report Date | B16: 42460 | C16: 42825 | D16: 43190 | E16: 43555 | F16: 43921 | G16: 44286 | H16: 44651 | I16: 45016 | J16: 45382 | K16: 45747
A17: Sales | B17: 14271.49 | C17: 15061.99 | D17: 16824.55 | E17: 19240.13 | F17: 20211.25 | G17: 21712.79 | H17: 29101.28 | I17: 34488.59 | J17: 35494.73 | K17: 33905.62
A18: Raw Material Cost | B18: 6569.83 | C18: 7452.6 | D18: 8128.17 | E18: 9974.4 | F18: 9986.19 | G18: 10425.55 | H18: 17123.25 | I18: 18985.53 | J18: 17410.84 | K18: 17504.51
A19: Change in Inventory | B19: -199.33 | C19: 528.6 | D19: -142.13 | E19: 293.26 | F19: 239.15 | G19: 92.45 | H19: 1324.97 | I19: 309.73 | J19: -363.8 | K19: 205
A20: Power and Fuel | B20: 114.48 | C20: 106.02 | D20: 110.3 | E20: 119.63 | F20: 114.93 | G20: 86.05 | H20: 117.23 | I20: 138.29 | J20: 133.25 | K20: 148.58
A21: Other Mfr. Exp | B21: 1535.22 | C21: 1662.75 | D21: 1691.68 | E21: 1862.35 | F21: 1941.92 | G21: 2068.31 | H21: 2880.45 | I21: 2916.2 | J21: 2767.18 | K21: 2687.4
A22: Employee Cost | B22: 994.98 | C22: 1039.89 | D22: 1121.89 | E22: 1242.69 | F22: 1371.27 | G22: 1547.61 | H22: 1794.61 | I22: 2036.41 | J22: 2334.92 | K22: 2605.78
A23: Selling and admin | B23: 3912.3 | C23: 4364.04 | D23: 2254.92 | E23: 2366.87 | F23: 2623.15 | G23: 2245.69 | H23: 2941.98 | I23: 3500.84 | J23: 3811.86 | K23: 3874.94
A24: Other Expenses | B24: -1779.69 | C24: -2028.47 | D24: 171.45 | E24: 202.51 | F24: 245.55 | G24: 576.43 | H24: 765.12 | I24: 961.21 | J24: 1087.9 | K24: 1283.2
A25: Other Income | B25: 213.39 | C25: 337.9 | D25: 336.41 | E25: 273.77 | F25: 350.1 | G25: 331.65 | H25: 295.88 | I25: 431.46 | J25: 820.96 | K25: 350.22
A26: Depreciation | B26: 275.58 | C26: 334.79 | D26: 360.47 | E26: 622.14 | F26: 780.5 | G26: 791.27 | H26: 816.36 | I26: 858.02 | J26: 853 | K26: 1026.34
A27: Interest | B27: 49 | C27: 37.33 | D27: 41.47 | E27: 110.47 | F27: 107.95 | G27: 91.63 | H27: 95.41 | I27: 144.45 | J27: 205.17 | K27: 227.02
... A31: Dividend Amount | B31: 719.4 | C31: 987.98 | D31: 834.5 | E31: 1007.16 | F31: 1151.04 | G31: 1712.17 | H31: 1836.87 | I31: 2460.35 | J31: 3194.14 | K31: 2378.82
A40: Quarters
A41: Report Date | B41: 45199 | C41: 45291 | D41: 45382 | E41: 45473 | F41: 45565 | G41: 45657 | H41: 45747 | I41: 45838 | J41: 45930 | K41: 46022
A42: Sales | B42: 8478.57 | C42: 9103.09 | D42: 8730.76 | E42: 8969.73 | F42: 8027.54 | G42: 8549.44 | H42: 8358.91 | I42: 8938.55 | J42: 8531.27 | K42: 8867.02
A43: Expenses | B43: 6762.34 | C43: 7047 | D43: 7039.39 | E43: 7275.96 | F43: 6788.03 | G43: 6912.71 | H43: 6922.71 | I43: 7313.58 | J43: 7027.89 | K43: 7086.06
A44: Other Income | B44: 194.33 | C44: 186.46 | D44: 212.43 | E44: 192.93 | F44: 24.53 | G44: 192.82 | H44: -60.06 | I44: 229.11 | J44: 236.94 | K44: 69.14
A45: Depreciation | B45: 208.72 | C45: 220.35 | D45: 225.61 | E45: 227.7 | F45: 241.99 | G45: 255.55 | H45: 301.1 | I45: 300.87 | J45: 304.93 | K45: 313.07
A46: Interest | B46: 50.9 | C46: 54.42 | D46: 54.1 | E46: 55.38 | F46: 63.01 | G46: 55.84 | H46: 52.79 | I46: 44.5 | J46: 43.87 | K46: 47.94
A47: Profit before tax | B47: 1650.94 | C47: 1967.78 | D47: 1624.09 | E47: 1603.62 | F47: 959.04 | G47: 1518.16 | H47: 1022.25 | I47: 1508.71 | J47: 1391.52 | K47: 1489.09
A48: Tax | B48: 418.55 | C48: 492.62 | D48: 348.79 | E48: 416.83 | F48: 265.38 | G48: 389.73 | H48: 321.42 | I48: 391.66 | J48: 373.29 | K48: 415.17
A49: Net profit | B49: 1205.42 | C49: 1447.72 | D49: 1256.72 | E49: 1169.98 | F49: 694.64 | G49: 1110.48 | H49: 692.13 | I49: 1099.77 | J49: 993.59 | K49: 1059.87
A50: Operating Profit | B50: 1716.23 | C50: 2056.09 | D50: 1691.37 | E50: 1693.77 | F50: 1239.51 | G50: 1636.73 | H50: 1436.2 | I50: 1624.97 | J50: 1503.38 | K50: 1780.96
A55: BALANCE SHEET
A56: Report Date | B56: 42460 | C56: 42825 | D56: 43190 | E56: 43555 | F56: 43921 | G56: 44286 | H56: 44651 | I56: 45016 | J56: 45382 | K56: 45747
A57: Equity Share Capital | B57: 95.92 | C57: 95.92 | D57: 95.92 | E57: 95.92 | F57: 95.92 | G57: 95.92 | H57: 95.92 | I57: 95.92 | J57: 95.92 | K57: 95.92
A58: Reserves | B58: 6428.9 | C58: 7507.97 | D58: 8314.31 | E58: 9374.63 | F58: 10034.24 | G58: 12710.37 | H58: 13715.64 | I58: 15896.31 | J58: 18632.38 | K58: 19303.89
A59: Borrowings | B59: 323.29 | C59: 560.34 | D59: 533.43 | E59: 1319.6 | F59: 1118.5 | G59: 1093.12 | H59: 1586.88 | I59: 1932.62 | J59: 2474.38 | K59: 2290.29
A60: Other Liabilities | B60: 3710.92 | C60: 4240.96 | D60: 4819.82 | E60: 5458.69 | F60: 4889.31 | G60: 6455.93 | H60: 7559.99 | I60: 7854.48 | J60: 8698.09 | K60: 8665.15
A61: Total | B61: 10559.03 | C61: 12405.19 | D61: 13763.48 | E61: 16248.84 | F61: 16137.97 | G61: 20355.34 | H61: 22958.43 | I61: 25779.33 | J61: 29900.77 | K61: 30355.25
...
